java.net.ConnectException: Call From ip-10-0-0-158/10.0.0.158 to localhost:9000 failed on connection exception: java.net.ConnectException: Connection refused; For more details see:  http://wiki.apache.org/hadoop/ConnectionRefused
	at sun.reflect.NativeConstructorAccessorImpl.newInstance0(Native Method)
	at sun.reflect.NativeConstructorAccessorImpl.newInstance(NativeConstructorAccessorImpl.java:57)
	at sun.reflect.DelegatingConstructorAccessorImpl.newInstance(DelegatingConstructorAccessorImpl.java:45)
	at java.lang.reflect.Constructor.newInstance(Constructor.java:526)
	at org.apache.hadoop.net.NetUtils.wrapWithMessage(NetUtils.java:783)
	at org.apache.hadoop.net.NetUtils.wrapException(NetUtils.java:730)
	at org.apache.hadoop.ipc.Client.call(Client.java:1351)
	at org.apache.hadoop.ipc.Client.call(Client.java:1300)
	at org.apache.hadoop.ipc.ProtobufRpcEngine$Invoker.invoke(ProtobufRpcEngine.java:206)
	at com.sun.proxy.$Proxy8.getTransactionId(Unknown Source)
	at sun.reflect.NativeMethodAccessorImpl.invoke0(Native Method)
	at sun.reflect.NativeMethodAccessorImpl.invoke(NativeMethodAccessorImpl.java:57)
	at sun.reflect.DelegatingMethodAccessorImpl.invoke(DelegatingMethodAccessorImpl.java:43)
	at java.lang.reflect.Method.invoke(Method.java:606)
	at org.apache.hadoop.io.retry.RetryInvocationHandler.invokeMethod(RetryInvocationHandler.java:186)
	at org.apache.hadoop.io.retry.RetryInvocationHandler.invoke(RetryInvocationHandler.java:102)
	at com.sun.proxy.$Proxy8.getTransactionId(Unknown Source)
	at org.apache.hadoop.hdfs.protocolPB.NamenodeProtocolTranslatorPB.getTransactionID(NamenodeProtocolTranslatorPB.java:119)
	at org.apache.hadoop.hdfs.server.namenode.SecondaryNameNode.countUncheckpointedTxns(SecondaryNameNode.java:622)
	at org.apache.hadoop.hdfs.server.namenode.SecondaryNameNode.shouldCheckpointBasedOnCount(SecondaryNameNode.java:630)
	at org.apache.hadoop.hdfs.server.namenode.SecondaryNameNode.doWork(SecondaryNameNode.java:378)
	at org.apache.hadoop.hdfs.server.namenode.SecondaryNameNode$2.run(SecondaryNameNode.java:346)
	at org.apache.hadoop.security.SecurityUtil.doAsLoginUserOrFatal(SecurityUtil.java:456)
	at org.apache.hadoop.hdfs.server.namenode.SecondaryNameNode.run(SecondaryNameNode.java:342)
	at java.lang.Thread.run(Thread.java:744)
Caused by: java.net.ConnectException: Connection refused
	at sun.nio.ch.SocketChannelImpl.checkConnect(Native Method)
	at sun.nio.ch.SocketChannelImpl.finishConnect(SocketChannelImpl.java:739)
	at org.apache.hadoop.net.SocketIOWithTimeout.connect(SocketIOWithTimeout.java:206)
	at org.apache.hadoop.net.NetUtils.connect(NetUtils.java:529)
	at org.apache.hadoop.net.NetUtils.connect(NetUtils.java:493)
	at org.apache.hadoop.ipc.Client$Connection.setupConnection(Client.java:547)
	at org.apache.hadoop.ipc.Client$Connection.setupIOstreams(Client.java:642)
	at org.apache.hadoop.ipc.Client$Connection.access$2600(Client.java:314)
	at org.apache.hadoop.ipc.Client.getConnection(Client.java:1399)
	at org.apache.hadoop.ipc.Client.call(Client.java:1318)
	... 18 more
java.net.ConnectException: Call From ip-10-0-0-158/10.0.0.158 to localhost:9000 failed on connection exception: java.net.ConnectException: Connection refused; For more details see:  http://wiki.apache.org/hadoop/ConnectionRefused
	at sun.reflect.NativeConstructorAccessorImpl.newInstance0(Native Method)
	at sun.reflect.NativeConstructorAccessorImpl.newInstance(NativeConstructorAccessorImpl.java:57)
	at sun.reflect.DelegatingConstructorAccessorImpl.newInstance(DelegatingConstructorAccessorImpl.java:45)
	at java.lang.reflect.Constructor.newInstance(Constructor.java:526)
	at org.apache.hadoop.net.NetUtils.wrapWithMessage(NetUtils.java:783)
	at org.apache.hadoop.net.NetUtils.wrapException(NetUtils.java:730)
	at org.apache.hadoop.ipc.Client.call(Client.java:1351)
	at org.apache.hadoop.ipc.Client.call(Client.java:1300)
	at org.apache.hadoop.ipc.ProtobufRpcEngine$Invoker.invoke(ProtobufRpcEngine.java:206)
	at com.sun.proxy.$Proxy8.getTransactionId(Unknown Source)
	at sun.reflect.NativeMethodAccessorImpl.invoke0(Native Method)
	at sun.reflect.NativeMethodAccessorImpl.invoke(NativeMethodAccessorImpl.java:57)
	at sun.reflect.DelegatingMethodAccessorImpl.invoke(DelegatingMethodAccessorImpl.java:43)
	at java.lang.reflect.Method.invoke(Method.java:606)
	at org.apache.hadoop.io.retry.RetryInvocationHandler.invokeMethod(RetryInvocationHandler.java:186)
	at org.apache.hadoop.io.retry.RetryInvocationHandler.invoke(RetryInvocationHandler.java:102)
	at com.sun.proxy.$Proxy8.getTransactionId(Unknown Source)
	at org.apache.hadoop.hdfs.protocolPB.NamenodeProtocolTranslatorPB.getTransactionID(NamenodeProtocolTranslatorPB.java:119)
	at org.apache.hadoop.hdfs.server.namenode.SecondaryNameNode.countUncheckpointedTxns(SecondaryNameNode.java:622)
	at org.apache.hadoop.hdfs.server.namenode.SecondaryNameNode.shouldCheckpointBasedOnCount(SecondaryNameNode.java:630)
	at org.apache.hadoop.hdfs.server.namenode.SecondaryNameNode.doWork(SecondaryNameNode.java:378)
	at org.apache.hadoop.hdfs.server.namenode.SecondaryNameNode$2.run(SecondaryNameNode.java:346)
	at org.apache.hadoop.security.SecurityUtil.doAsLoginUserOrFatal(SecurityUtil.java:456)
	at org.apache.hadoop.hdfs.server.namenode.SecondaryNameNode.run(SecondaryNameNode.java:342)
	at java.lang.Thread.run(Thread.java:744)
Caused by: java.net.ConnectException: Connection refused
	at sun.nio.ch.SocketChannelImpl.checkConnect(Native Method)
	at sun.nio.ch.SocketChannelImpl.finishConnect(SocketChannelImpl.java:739)
	at org.apache.hadoop.net.SocketIOWithTimeout.connect(SocketIOWithTimeout.java:206)
	at org.apache.hadoop.net.NetUtils.connect(NetUtils.java:529)
	at org.apache.hadoop.net.NetUtils.connect(NetUtils.java:493)
	at org.apache.hadoop.ipc.Client$Connection.setupConnection(Client.java:547)
	at org.apache.hadoop.ipc.Client$Connection.setupIOstreams(Client.java:642)
	at org.apache.hadoop.ipc.Client$Connection.access$2600(Client.java:314)
	at org.apache.hadoop.ipc.Client.getConnection(Client.java:1399)
	at org.apache.hadoop.ipc.Client.call(Client.java:1318)
	... 18 more
java.net.ConnectException: Call From ip-10-0-0-158/10.0.0.158 to localhost:9000 failed on connection exception: java.net.ConnectException: Connection refused; For more details see:  http://wiki.apache.org/hadoop/ConnectionRefused
	at sun.reflect.NativeConstructorAccessorImpl.newInstance0(Native Method)
	at sun.reflect.NativeConstructorAccessorImpl.newInstance(NativeConstructorAccessorImpl.java:57)
	at sun.reflect.DelegatingConstructorAccessorImpl.newInstance(DelegatingConstructorAccessorImpl.java:45)
	at java.lang.reflect.Constructor.newInstance(Constructor.java:526)
	at org.apache.hadoop.net.NetUtils.wrapWithMessage(NetUtils.java:783)
	at org.apache.hadoop.net.NetUtils.wrapException(NetUtils.java:730)
	at org.apache.hadoop.ipc.Client.call(Client.java:1351)
	at org.apache.hadoop.ipc.Client.call(Client.java:1300)
	at org.apache.hadoop.ipc.ProtobufRpcEngine$Invoker.invoke(ProtobufRpcEngine.java:206)
	at com.sun.proxy.$Proxy8.getTransactionId(Unknown Source)
	at sun.reflect.NativeMethodAccessorImpl.invoke0(Native Method)
	at sun.reflect.NativeMethodAccessorImpl.invoke(NativeMethodAccessorImpl.java:57)
	at sun.reflect.DelegatingMethodAccessorImpl.invoke(DelegatingMethodAccessorImpl.java:43)
	at java.lang.reflect.Method.invoke(Method.java:606)
	at org.apache.hadoop.io.retry.RetryInvocationHandler.invokeMethod(RetryInvocationHandler.java:186)
	at org.apache.hadoop.io.retry.RetryInvocationHandler.invoke(RetryInvocationHandler.java:102)
	at com.sun.proxy.$Proxy8.getTransactionId(Unknown Source)
	at org.apache.hadoop.hdfs.protocolPB.NamenodeProtocolTranslatorPB.getTransactionID(NamenodeProtocolTranslatorPB.java:119)
	at org.apache.hadoop.hdfs.server.namenode.SecondaryNameNode.countUncheckpointedTxns(SecondaryNameNode.java:622)
	at org.apache.hadoop.hdfs.server.namenode.SecondaryNameNode.shouldCheckpointBasedOnCount(SecondaryNameNode.java:630)
	at org.apache.hadoop.hdfs.server.namenode.SecondaryNameNode.doWork(SecondaryNameNode.java:378)
	at org.apache.hadoop.hdfs.server.namenode.SecondaryNameNode$2.run(SecondaryNameNode.java:346)
	at org.apache.hadoop.security.SecurityUtil.doAsLoginUserOrFatal(SecurityUtil.java:456)
	at org.apache.hadoop.hdfs.server.namenode.SecondaryNameNode.run(SecondaryNameNode.java:342)
	at java.lang.Thread.run(Thread.java:744)
Caused by: java.net.ConnectException: Connection refused
	at sun.nio.ch.SocketChannelImpl.checkConnect(Native Method)
	at sun.nio.ch.SocketChannelImpl.finishConnect(SocketChannelImpl.java:739)
	at org.apache.hadoop.net.SocketIOWithTimeout.connect(SocketIOWithTimeout.java:206)
	at org.apache.hadoop.net.NetUtils.connect(NetUtils.java:529)
	at org.apache.hadoop.net.NetUtils.connect(NetUtils.java:493)
	at org.apache.hadoop.ipc.Client$Connection.setupConnection(Client.java:547)
	at org.apache.hadoop.ipc.Client$Connection.setupIOstreams(Client.java:642)
	at org.apache.hadoop.ipc.Client$Connection.access$2600(Client.java:314)
	at org.apache.hadoop.ipc.Client.getConnection(Client.java:1399)
	at org.apache.hadoop.ipc.Client.call(Client.java:1318)
	... 18 more
java.net.ConnectException: Call From ip-10-0-0-158/10.0.0.158 to localhost:9000 failed on connection exception: java.net.ConnectException: Connection refused; For more details see:  http://wiki.apache.org/hadoop/ConnectionRefused
	at sun.reflect.NativeConstructorAccessorImpl.newInstance0(Native Method)
	at sun.reflect.NativeConstructorAccessorImpl.newInstance(NativeConstructorAccessorImpl.java:57)
	at sun.reflect.DelegatingConstructorAccessorImpl.newInstance(DelegatingConstructorAccessorImpl.java:45)
	at java.lang.reflect.Constructor.newInstance(Constructor.java:526)
	at org.apache.hadoop.net.NetUtils.wrapWithMessage(NetUtils.java:783)
	at org.apache.hadoop.net.NetUtils.wrapException(NetUtils.java:730)
	at org.apache.hadoop.ipc.Client.call(Client.java:1351)
	at org.apache.hadoop.ipc.Client.call(Client.java:1300)
	at org.apache.hadoop.ipc.ProtobufRpcEngine$Invoker.invoke(ProtobufRpcEngine.java:206)
	at com.sun.proxy.$Proxy8.getTransactionId(Unknown Source)
	at sun.reflect.NativeMethodAccessorImpl.invoke0(Native Method)
	at sun.reflect.NativeMethodAccessorImpl.invoke(NativeMethodAccessorImpl.java:57)
	at sun.reflect.DelegatingMethodAccessorImpl.invoke(DelegatingMethodAccessorImpl.java:43)
	at java.lang.reflect.Method.invoke(Method.java:606)
	at org.apache.hadoop.io.retry.RetryInvocationHandler.invokeMethod(RetryInvocationHandler.java:186)
	at org.apache.hadoop.io.retry.RetryInvocationHandler.invoke(RetryInvocationHandler.java:102)
	at com.sun.proxy.$Proxy8.getTransactionId(Unknown Source)
	at org.apache.hadoop.hdfs.protocolPB.NamenodeProtocolTranslatorPB.getTransactionID(NamenodeProtocolTranslatorPB.java:119)
	at org.apache.hadoop.hdfs.server.namenode.SecondaryNameNode.countUncheckpointedTxns(SecondaryNameNode.java:622)
	at org.apache.hadoop.hdfs.server.namenode.SecondaryNameNode.shouldCheckpointBasedOnCount(SecondaryNameNode.java:630)
	at org.apache.hadoop.hdfs.server.namenode.SecondaryNameNode.doWork(SecondaryNameNode.java:378)
	at org.apache.hadoop.hdfs.server.namenode.SecondaryNameNode$2.run(SecondaryNameNode.java:346)
	at org.apache.hadoop.security.SecurityUtil.doAsLoginUserOrFatal(SecurityUtil.java:456)
	at org.apache.hadoop.hdfs.server.namenode.SecondaryNameNode.run(SecondaryNameNode.java:342)
	at java.lang.Thread.run(Thread.java:744)
Caused by: java.net.ConnectException: Connection refused
	at sun.nio.ch.SocketChannelImpl.checkConnect(Native Method)
	at sun.nio.ch.SocketChannelImpl.finishConnect(SocketChannelImpl.java:739)
	at org.apache.hadoop.net.SocketIOWithTimeout.connect(SocketIOWithTimeout.java:206)
	at org.apache.hadoop.net.NetUtils.connect(NetUtils.java:529)
	at org.apache.hadoop.net.NetUtils.connect(NetUtils.java:493)
	at org.apache.hadoop.ipc.Client$Connection.setupConnection(Client.java:547)
	at org.apache.hadoop.ipc.Client$Connection.setupIOstreams(Client.java:642)
	at org.apache.hadoop.ipc.Client$Connection.access$2600(Client.java:314)
	at org.apache.hadoop.ipc.Client.getConnection(Client.java:1399)
	at org.apache.hadoop.ipc.Client.call(Client.java:1318)
	... 18 more
